<?xml version="1.0"?>
<!-- created with Phobos 1.0.1 "Capricious Choutengan" -->
<robot name="bittle" xmlns:xacro="http://www.ros.org/wiki/xacro">
  <xacro:include filename="$(find bittle)/model/materials.xacro" />

  <link name="dummy">
  </link>

  <link name="base-frame-link">
    <inertial>
      <origin xyz="0 0 0" rpy="0 0 0"/>
      <mass value="0.108"/>
      <inertia ixx="0.01562" ixy="0" ixz="-2e-05" iyy="0.00613" iyz="0" izz="0.02107"/>
    </inertial>
    <visual name="base_frame">
      <origin xyz="0 0 0" rpy="0 0 0"/>
      <geometry>
        <mesh filename="$(find bittle)/meshes/base_frame.obj" scale="1.0 1.0 1.0"/>
      </geometry>
      <material name="white"/>
    </visual>
    <collision name="base_frame_c">
      <origin xyz="0 0 0" rpy="0 0 0"/>
      <geometry>
        <mesh filename="$(find bittle)/meshes/base_frame.001.obj" scale="1.0 1.0 1.0"/>
      </geometry>
    </collision>
  </link>

  <link name="battery-link">
    <inertial>
      <origin xyz="0 0 0" rpy="0 0 0"/>
      <mass value="0.056"/>
      <inertia ixx="0.00337" ixy="0" ixz="0" iyy="0.00044" iyz="0.00031" izz="0.00361"/>
    </inertial>
    <visual name="battery">
      <origin xyz="0 0 0" rpy="0 0 0"/>
      <geometry>
        <mesh filename="$(find bittle)/meshes/battery.obj" scale="1.0 1.0 1.0"/>
      </geometry>
      <material name="white"/>
    </visual>
    <collision name="battery_c">
      <origin xyz="0 0 0" rpy="0 0 0"/>
      <geometry>
        <mesh filename="$(find bittle)/meshes/battery.001.obj" scale="1.0 1.0 1.0"/>
      </geometry>
    </collision>
  </link>

  <link name="cover-link">
    <inertial>
      <origin xyz="0 0 0" rpy="0 0 0"/>
      <mass value="0.013"/>
      <inertia ixx="0.00039" ixy="0" ixz="0" iyy="0.00057" iyz="0" izz="0.0009"/>
    </inertial>
    <visual name="cover">
      <origin xyz="0 0 0" rpy="0 0 0"/>
      <geometry>
        <mesh filename="$(find bittle)/meshes/cover.obj" scale="1.0 1.0 1.0"/>
      </geometry>
      <material name="white"/>
    </visual>
    <collision name="cover_c">
      <origin xyz="0 0 0" rpy="0 0 0"/>
      <geometry>
        <mesh filename="$(find bittle)/meshes/cover.001.obj" scale="1.0 1.0 1.0"/>
      </geometry>
    </collision>
  </link>

  <link name="imu_link">
    <inertial>
      <origin xyz="0 0 0" rpy="0 0 0"/>
      <mass value="0.001"/>
      <inertia ixx="0.001" ixy="0" ixz="0" iyy="0.001" iyz="0" izz="0.001"/>
    </inertial>
    <visual name="imu">
      <origin xyz="0 0 0" rpy="0 0 3.14159"/>
      <geometry>
        <mesh filename="$(find bittle)/meshes/Cube.011.obj" scale="1.0 1.0 1.0"/>
      </geometry>
      <material name="white"/>
    </visual>
  </link>

  <link name="left_back_knee_link">
    <inertial>
      <origin xyz="-0.08998 0 -0.14638" rpy="0 0 0"/>
      <mass value="0.017"/>
      <inertia ixx="0.00004" ixy="0" ixz="0" iyy="0.0004" iyz="0" izz="0.0004"/>
    </inertial>
    <visual name="left_back_knee">
      <origin xyz="-0.08998 0 -0.14638" rpy="-1.5708 1.5708 0"/>
      <geometry>
        <mesh filename="$(find bittle)/meshes/left_knee.001.obj" scale="1.0 1.0 1.0"/>
      </geometry>
      <material name="white"/>
    </visual>
    <collision name="left_back_knee_c">
      <origin xyz="-0.08998 0 -0.14638" rpy="-1.5708 1.5708 0"/>
      <geometry>
        <mesh filename="$(find bittle)/meshes/left_knee.002.obj" scale="1.0 1.0 1.0"/>
      </geometry>
    </collision>
  </link>

  <link name="left_back_shoulder_link">
    <inertial>
      <origin xyz="0 -0.24575 0.04372" rpy="0 0 0"/>
      <mass value="0.006"/>
      <inertia ixx="0.00044" ixy="0" ixz="0" iyy="2e-05" iyz="0" izz="0.00044"/>
    </inertial>
    <visual name="left_back_shoulder">
      <origin xyz="0 -0.24575 0.04372" rpy="-1.5708 1.5708 0"/>
      <geometry>
        <mesh filename="$(find bittle)/meshes/shoulder.001.obj" scale="1.0 1.0 1.0"/>
      </geometry>
      <material name="white"/>
    </visual>
    <collision name="left_back_shoulder_c">
      <origin xyz="0 -0.24575 0.04372" rpy="-1.5708 1.5708 0"/>
      <geometry>
        <mesh filename="$(find bittle)/meshes/shoulder.004.obj" scale="1.0 1.0 1.0"/>
      </geometry>
    </collision>
  </link>

  <link name="left_front_knee_link">
    <inertial>
      <origin xyz="-0.09232 0 -0.14614" rpy="0 0 0"/>
      <mass value="0.017"/>
      <inertia ixx="0.00004" ixy="0" ixz="0" iyy="0.0004" iyz="0" izz="0.0004"/>
    </inertial>
    <visual name="left_front_knee">
      <origin xyz="-0.09232 0 -0.14614" rpy="-1.5708 1.5708 0"/>
      <geometry>
        <mesh filename="$(find bittle)/meshes/left_knee.obj" scale="1.0 1.0 1.0"/>
      </geometry>
      <material name="white"/>
    </visual>
    <collision name="left_front_knee_c">
      <origin xyz="-0.09232 0 -0.14614" rpy="-1.5708 1.5708 0"/>
      <geometry>
        <mesh filename="$(find bittle)/meshes/left_knee.003.obj" scale="1.0 1.0 1.0"/>
      </geometry>
    </collision>
  </link>

  <link name="left_front_shoulder_link">
    <inertial>
      <origin xyz="0 -0.24575 0.04372" rpy="0 0 0"/>
      <mass value="0.006"/>
      <inertia ixx="0.00044" ixy="0" ixz="0" iyy="2e-05" iyz="0" izz="0.00044"/>
    </inertial>
    <visual name="left_front_shoulder">
      <origin xyz="0 -0.24575 0.04372" rpy="-1.5708 1.5708 0"/>
      <geometry>
        <mesh filename="$(find bittle)/meshes/shoulder.obj" scale="1.0 1.0 1.0"/>
      </geometry>
      <material name="white"/>
    </visual>
    <collision name="left_front_shoulder_c">
      <origin xyz="0 -0.24575 0.04372" rpy="-1.5708 1.5708 0"/>
      <geometry>
        <mesh filename="$(find bittle)/meshes/shoulder.007.obj" scale="1.0 1.0 1.0"/>
      </geometry>
    </collision>
  </link>

  <link name="mainboard_link">
    <inertial>
      <origin xyz="0 0 0" rpy="0 0 0"/>
      <mass value="0.001"/>
      <inertia ixx="0.001" ixy="0" ixz="0" iyy="0.001" iyz="0" izz="0.001"/>
    </inertial>
    <visual name="mainboard">
      <origin xyz="0 0 0" rpy="0 0 0"/>
      <geometry>
        <mesh filename="$(find bittle)/meshes/Plane.obj" scale="1.0 1.0 1.0"/>
      </geometry>
      <material name="white"/>
    </visual>
  </link>

  <link name="right_back_knee_link">
    <inertial>
      <origin xyz="0.08426 -0.00238 -0.1382" rpy="0 0 0"/>
      <mass value="0.017"/>
      <inertia ixx="0.00004" ixy="0" ixz="0" iyy="0.0004" iyz="0" izz="0.0004"/>
    </inertial>
    <visual name="right_back_knee">
      <origin xyz="0.08426 -0.00238 -0.1382" rpy="-1.5708 -1.5708 0"/>
      <geometry>
        <mesh filename="$(find bittle)/meshes/right_knee.001.obj" scale="1.0 1.0 1.0"/>
      </geometry>
      <material name="white"/>
    </visual>
    <collision name="right_back_knee_c">
      <origin xyz="0.08426 -0.00238 -0.1382" rpy="-1.5708 -1.5708 0"/>
      <geometry>
        <mesh filename="$(find bittle)/meshes/right_knee.002.obj" scale="1.0 1.0 1.0"/>
      </geometry>
    </collision>
  </link>

  <link name="right_back_shoulder_link">
    <inertial>
      <origin xyz="0 0.24575 0.0777" rpy="0 0 0"/>
      <mass value="0.006"/>
      <inertia ixx="0.00044" ixy="0" ixz="0" iyy="2e-05" iyz="0" izz="0.00044"/>
    </inertial>
    <visual name="right_back_shoulder">
      <origin xyz="0 0.24575 0.0777" rpy="1.5708 -1.5708 0"/>
      <geometry>
        <mesh filename="$(find bittle)/meshes/shoulder.002.obj" scale="1.0 1.0 1.0"/>
      </geometry>
      <material name="white"/>
    </visual>
    <collision name="right_back_shoulder_c">
      <origin xyz="0 0.24575 0.0777" rpy="1.5708 -1.5708 0"/>
      <geometry>
        <mesh filename="$(find bittle)/meshes/shoulder.005.obj" scale="1.0 1.0 1.0"/>
      </geometry>
    </collision>
  </link>

  <link name="right_front_knee_link">
    <inertial>
      <origin xyz="0.09497 -0.00238 -0.1382" rpy="0 0 0"/>
      <mass value="0.017"/>
      <inertia ixx="0.00004" ixy="0" ixz="0" iyy="0.0004" iyz="0" izz="0.0004"/>
    </inertial>
    <visual name="right_front_knee">
      <origin xyz="0.09497 -0.00238 -0.1382" rpy="-1.5708 -1.5708 0"/>
      <geometry>
        <mesh filename="$(find bittle)/meshes/right_knee.obj" scale="1.0 1.0 1.0"/>
      </geometry>
      <material name="white"/>
    </visual>
    <collision name="right_front_knee_c">
      <origin xyz="0.09497 -0.00238 -0.1382" rpy="-1.5708 -1.5708 0"/>
      <geometry>
        <mesh filename="$(find bittle)/meshes/right_knee.003.obj" scale="1.0 1.0 1.0"/>
      </geometry>
    </collision>
  </link>

  <link name="right_front_shoulder_link">
    <inertial>
      <origin xyz="0 0.24575 0.0777" rpy="0 0 0"/>
      <mass value="0.006"/>
      <inertia ixx="0.00044" ixy="0" ixz="0" iyy="2e-05" iyz="0" izz="0.00044"/>
    </inertial>
    <visual name="right_front_shoulder">
      <origin xyz="0 0.24575 0.0777" rpy="1.5708 -1.5708 0"/>
      <geometry>
        <mesh filename="$(find bittle)/meshes/shoulder.003.obj" scale="1.0 1.0 1.0"/>
      </geometry>
      <material name="white"/>
    </visual>
    <collision name="right_front_shoulder_c">
      <origin xyz="0 0.24575 0.0777" rpy="1.5708 -1.5708 0"/>
      <geometry>
        <mesh filename="$(find bittle)/meshes/shoulder.006.obj" scale="1.0 1.0 1.0"/>
      </geometry>
    </collision>
  </link>

  <joint name="attach" type="fixed">
    <parent link="dummy"/>
    <child link="base-frame-link"/>
  </joint>

  <joint name="battery-joint" type="fixed">
    <origin xyz="0.00047 -0.00917 -0.04848" rpy="0 0 0"/>
    <parent link="base-frame-link"/>
    <child link="battery-link"/>
  </joint>

  <joint name="cover-joint" type="fixed">
    <origin xyz="0.0014 0 0.1251" rpy="0 0 0"/>
    <parent link="base-frame-link"/>
    <child link="cover-link"/>
  </joint>

  <joint name="imu_joint" type="fixed">
    <origin xyz="-0.00652 0.00827 0.00586" rpy="0 0 -3.14159"/>
    <parent link="mainboard_link"/>
    <child link="imu_link"/>
  </joint>

  <joint name="left_back_knee_joint" type="revolute">
    <origin xyz="0 -0.49172 0" rpy="0 0 0"/>
    <parent link="left_back_shoulder_link"/>
    <child link="left_back_knee_link"/>
    <axis xyz="0 0 1.0"/>
    <limit lower="-1.22173" upper="1.48353" effort="1.0" velocity="1.5708"/>
  </joint>

  <joint name="left_back_shoulder_joint" type="revolute">
    <origin xyz="-0.44596 -0.51923 -0.02102" rpy="1.5708 0 -1.5708"/>
    <parent link="base-frame-link"/>
    <child link="left_back_shoulder_link"/>
    <axis xyz="0 0 1.0"/>
    <limit lower="-1.5708" upper="1.22173" effort="1.0" velocity="1.5708"/>
  </joint>

  <joint name="left_front_knee_joint" type="revolute">
    <origin xyz="6e-05 -0.49172 0" rpy="0 0 0"/>
    <parent link="left_front_shoulder_link"/>
    <child link="left_front_knee_link"/>
    <axis xyz="0 0 1.0"/>
    <limit lower="-1.22173" upper="1.48353" effort="1.0" velocity="1.5708"/>
  </joint>

  <joint name="left_front_shoulder_joint" type="revolute">
    <origin xyz="-0.44596 0.52264 -0.02102" rpy="1.5708 0 -1.5708"/>
    <parent link="base-frame-link"/>
    <child link="left_front_shoulder_link"/>
    <axis xyz="0 0 1.0"/>
    <limit lower="-1.5708" upper="1.22173" effort="1.0" velocity="1.5708"/>
  </joint>

  <joint name="mainboard_joint" type="fixed">
    <origin xyz="0.00652 -0.00827 0.06423" rpy="0 0 0"/>
    <parent link="base-frame-link"/>
    <child link="mainboard_link"/>
  </joint>

  <joint name="right_back_knee_joint" type="revolute">
    <origin xyz="0.00015 0.49938 0.03996" rpy="0 0 3.14159"/>
    <parent link="right_back_shoulder_link"/>
    <child link="right_back_knee_link"/>
    <axis xyz="0 0 1.0"/>
    <limit lower="-1.22173" upper="1.48353" effort="1.0" velocity="1.5708"/>
  </joint>

  <joint name="right_back_shoulder_joint" type="revolute">
    <origin xyz="0.45149 -0.51923 -0.02102" rpy="-1.5708 0 -1.5708"/>
    <parent link="base-frame-link"/>
    <child link="right_back_shoulder_link"/>
    <axis xyz="0 0 1.0"/>
    <limit lower="-1.5708" upper="1.22173" effort="1.0" velocity="1.5708"/>
  </joint>

  <joint name="right_front_knee_joint" type="revolute">
    <origin xyz="6e-05 0.49938 0.03996" rpy="0 0 3.14159"/>
    <parent link="right_front_shoulder_link"/>
    <child link="right_front_knee_link"/>
    <axis xyz="0 0 1.0"/>
    <limit lower="-1.22173" upper="1.48353" effort="1.0" velocity="1.5708"/>
  </joint>

  <joint name="right_front_shoulder_joint" type="revolute">
    <origin xyz="0.45149 0.52264 -0.02102" rpy="-1.5708 0 -1.5708"/>
    <parent link="base-frame-link"/>
    <child link="right_front_shoulder_link"/>
    <axis xyz="0 0 1.0"/>
    <limit lower="-1.5708" upper="1.22173" effort="1.0" velocity="1.5708"/>
  </joint>

  <ros2_control name="GazeboSimSystem" type="system">
    <hardware>
      <plugin>gz_ros2_control/GazeboSimSystem</plugin>
    </hardware>
    <joint name="left_back_knee_joint">
      <command_interface name="position">
        <param name="min">0</param>
        <param name="max">1.57</param>
      </command_interface>
      <state_interface name="position">
        <param name="initial_value">0</param>
      </state_interface>
    </joint>
    <joint name="left_back_shoulder_joint">
      <command_interface name="position">
        <param name="min">0</param>
        <param name="max">1.57</param>
      </command_interface>
      <state_interface name="position">
        <param name="initial_value">0</param>
      </state_interface>
    </joint>
    <joint name="left_front_knee_joint">
      <command_interface name="position">
        <param name="min">0</param>
        <param name="max">1.57</param>
      </command_interface>
      <state_interface name="position">
        <param name="initial_value">0</param>
      </state_interface>
    </joint>
    <joint name="left_front_shoulder_joint">
      <command_interface name="position">
        <param name="min">0</param>
        <param name="max">1.57</param>
      </command_interface>
      <state_interface name="position">
        <param name="initial_value">0</param>
      </state_interface>
    </joint>
    <joint name="right_back_knee_joint">
      <command_interface name="position">
        <param name="min">0</param>
        <param name="max">1.57</param>
      </command_interface>
      <state_interface name="position">
        <param name="initial_value">0</param>
      </state_interface>
    </joint>
    <joint name="right_back_shoulder_joint">
      <command_interface name="position">
        <param name="min">0</param>
        <param name="max">1.57</param>
      </command_interface>
      <state_interface name="position">
        <param name="initial_value">0</param>
      </state_interface>
    </joint>
    <joint name="right_front_knee_joint">
      <command_interface name="position">
        <param name="min">0</param>
        <param name="max">1.57</param>
      </command_interface>
      <state_interface name="position">
        <param name="initial_value">0</param>
      </state_interface>
    </joint>
    <joint name="right_front_shoulder_joint">
      <command_interface name="position">
        <param name="min">0</param>
        <param name="max">1.57</param>
      </command_interface>
      <state_interface name="position">
        <param name="initial_value">0</param>
      </state_interface>
    </joint>
  </ros2_control>
  <xacro:include filename="$(find bittle)/model/gazebo.xacro" />
</robot>
